<sdf version='1.7'>
  <world name='default'>
    <gui fullscreen='0'>
      <camera name='gzclient_camera'>
        <pose>15.6793 -20.0498 12.8232 0 0.400753 2.43537</pose>
        <view_controller>orbit</view_controller>
        <projection_type>perspective</projection_type>
      </camera>
    </gui>
    <gravity>0 0 -9.8</gravity>
    <magnetic_field>6e-06 2.3e-05 -4.2e-05</magnetic_field>
    <atmosphere type='adiabatic'/>
    <physics name='default_physics' default='0' type='ode'>
      <max_step_size>0.001</max_step_size>
      <real_time_factor>1</real_time_factor>
      <real_time_update_rate>1000</real_time_update_rate>
    </physics>
    <scene>
      <ambient>0.4 0.4 0.4 1</ambient>
      <background>0.7 0.7 0.7 1</background>
      <shadows>1</shadows>
    </scene>
    <spherical_coordinates>
      <surface_model>EARTH_WGS84</surface_model>
      <latitude_deg>0</latitude_deg>
      <longitude_deg>0</longitude_deg>
      <elevation>0</elevation>
      <heading_deg>0</heading_deg>
    </spherical_coordinates>
    <model name='aws_robomaker_racetrack_Track_05_00'>
      <frame name='aws_Track_05::__model__' attached_to='aws_Track_05::body'>
        <pose relative_to='__model__'>0 0 0 0 -0 0</pose>
      </frame>
      <link name='aws_Track_05::body'>
        <pose relative_to='aws_Track_05::__model__'>0 0 0 0 -0 0</pose>
        <self_collide>0</self_collide>
        <kinematic>0</kinematic>
        <gravity>1</gravity>
        <inertial>
          <mass>1000</mass>
          <pose>0 0 0 0 -0 0</pose>
          <inertia>
            <ixx>1</ixx>
            <ixy>0</ixy>
            <ixz>0</ixz>
            <iyy>1</iyy>
            <iyz>0</iyz>
            <izz>1</izz>
          </inertia>
        </inertial>
        <visual name='visual'>
          <geometry>
            <mesh>
              <uri>file://models/aws_robomaker_racetrack_Track_05/meshes/aws_Track_05_visual.DAE</uri>
            </mesh>
          </geometry>
          <material>
            <shader type='pixel'>
              <normal_map>__default__</normal_map>
            </shader>
          </material>
          <pose>0 0 0 0 -0 0</pose>
          <cast_shadows>1</cast_shadows>
          <transparency>0</transparency>
          <meta>
            <layer>0</layer>
          </meta>
        </visual>
        <collision name='collision_0'>
          <laser_retro>0</laser_retro>
          <max_contacts>10</max_contacts>
          <pose>0 0 0 0 -0 0</pose>
          <geometry>
            <mesh>
              <uri>file://models/aws_robomaker_racetrack_Track_05/meshes/aws_Track_05_collision.DAE</uri>
              <scale>1 1 1</scale>
            </mesh>
          </geometry>
          <surface>
            <friction>
              <ode>
                <mu>100</mu>
                <mu2>50</mu2>
                <fdir1>0 0 0</fdir1>
                <slip1>0</slip1>
                <slip2>0</slip2>
              </ode>
              <torsional>
                <coefficient>1</coefficient>
                <patch_radius>0</patch_radius>
                <surface_radius>0</surface_radius>
                <use_patch_radius>1</use_patch_radius>
                <ode>
                  <slip>0</slip>
                </ode>
              </torsional>
            </friction>
            <bounce>
              <restitution_coefficient>0</restitution_coefficient>
              <threshold>1e+06</threshold>
            </bounce>
            <contact>
              <collide_without_contact>0</collide_without_contact>
              <collide_without_contact_bitmask>1</collide_without_contact_bitmask>
              <collide_bitmask>1</collide_bitmask>
              <ode>
                <soft_cfm>0</soft_cfm>
                <soft_erp>0.2</soft_erp>
                <kp>1e+13</kp>
                <kd>1</kd>
                <max_vel>0.01</max_vel>
                <min_depth>0</min_depth>
              </ode>
              <bullet>
                <split_impulse>1</split_impulse>
                <split_impulse_penetration_threshold>-0.01</split_impulse_penetration_threshold>
                <soft_cfm>0</soft_cfm>
                <soft_erp>0.2</soft_erp>
                <kp>1e+13</kp>
                <kd>1</kd>
              </bullet>
            </contact>
          </surface>
        </collision>
        <enable_wind>0</enable_wind>
      </link>
      <static>1</static>
      <pose>0 0 0.051 0 -0 0</pose>
    </model>
    <model name='aws_robomaker_racetrack_Trackline_01_00'>
      <frame name='aws_Trackline_01::__model__' attached_to='aws_Trackline_01::body'>
        <pose relative_to='__model__'>0 0 0 0 -0 0</pose>
      </frame>
      <link name='aws_Trackline_01::body'>
        <pose relative_to='aws_Trackline_01::__model__'>0 0 0 0 -0 0</pose>
        <inertial>
          <mass>0.5</mass>
          <pose>0 0 0 0 -0 0</pose>
          <inertia>
            <ixx>1</ixx>
            <ixy>0</ixy>
            <ixz>0</ixz>
            <iyy>1</iyy>
            <iyz>0</iyz>
            <izz>1</izz>
          </inertia>
        </inertial>
        <self_collide>0</self_collide>
        <kinematic>0</kinematic>
        <gravity>1</gravity>
        <visual name='visual'>
          <geometry>
            <mesh>
              <uri>file://models/aws_robomaker_racetrack_Trackline_01/meshes/aws_Trackline_01_visual.DAE</uri>
            </mesh>
          </geometry>
          <material>
            <shader type='pixel'>
              <normal_map>__default__</normal_map>
            </shader>
          </material>
          <pose>0 0 0 0 -0 0</pose>
          <cast_shadows>1</cast_shadows>
          <transparency>0</transparency>
          <meta>
            <layer>0</layer>
          </meta>
        </visual>
        <collision name='collision_0'>
          <laser_retro>0</laser_retro>
          <max_contacts>10</max_contacts>
          <pose>0 0 0 0 -0 0</pose>
          <geometry>
            <mesh>
              <uri>file://models/aws_robomaker_racetrack_Trackline_01/meshes/aws_Trackline_01_collision.DAE</uri>
              <scale>1 1 1</scale>
            </mesh>
          </geometry>
          <surface>
            <friction>
              <ode>
                <mu>1</mu>
                <mu2>1</mu2>
                <fdir1>0 0 0</fdir1>
                <slip1>0</slip1>
                <slip2>0</slip2>
              </ode>
              <torsional>
                <coefficient>1</coefficient>
                <patch_radius>0</patch_radius>
                <surface_radius>0</surface_radius>
                <use_patch_radius>1</use_patch_radius>
                <ode>
                  <slip>0</slip>
                </ode>
              </torsional>
            </friction>
            <bounce>
              <restitution_coefficient>0</restitution_coefficient>
              <threshold>1e+06</threshold>
            </bounce>
            <contact>
              <collide_without_contact>0</collide_without_contact>
              <collide_without_contact_bitmask>1</collide_without_contact_bitmask>
              <collide_bitmask>0</collide_bitmask>
              <ode>
                <soft_cfm>0</soft_cfm>
                <soft_erp>0.2</soft_erp>
                <kp>1e+13</kp>
                <kd>1</kd>
                <max_vel>0.01</max_vel>
                <min_depth>0</min_depth>
              </ode>
              <bullet>
                <split_impulse>1</split_impulse>
                <split_impulse_penetration_threshold>-0.01</split_impulse_penetration_threshold>
                <soft_cfm>0</soft_cfm>
                <soft_erp>0.2</soft_erp>
                <kp>1e+13</kp>
                <kd>1</kd>
              </bullet>
            </contact>
          </surface>
        </collision>
        <enable_wind>0</enable_wind>
      </link>
      <static>1</static>
      <pose>-4.24539 0 0.102 0 -0 0</pose>
    </model>
    <model name='ground_plane'>
      <pose>0 0 -1 0 -0 0</pose>
      <link name='link'>
        <pose>0 0 -1 0 -0 0</pose>
        <self_collide>0</self_collide>
        <inertial>
          <pose>0 0 0 0 -0 0</pose>
          <inertia>
            <ixx>1</ixx>
            <ixy>0</ixy>
            <ixz>0</ixz>
            <iyy>1</iyy>
            <iyz>0</iyz>
            <izz>1</izz>
          </inertia>
          <mass>1</mass>
        </inertial>
        <enable_wind>0</enable_wind>
        <kinematic>0</kinematic>
        <velocity>0 0 0 0 -0 0</velocity>
        <acceleration>0 0 0 0 -0 0</acceleration>
      </link>
      <scale>1 1 1</scale>
    </model>
    <state world_name='default'>
      <sim_time>7599 718000000</sim_time>
      <real_time>190 467108457</real_time>
      <wall_time>1745987931 425985404</wall_time>
      <iterations>189827</iterations>
      <model name='aws_robomaker_racetrack_Track_05_00'>
        <pose>0 0 0.051 0 -0 0</pose>
        <scale>1 1 1</scale>
        <link name='aws_Track_05::body'>
          <pose>0 0 0.051 0 -0 0</pose>
          <velocity>0 0 0 0 -0 0</velocity>
          <acceleration>0 0 0 0 -0 0</acceleration>
          <wrench>0 0 0 0 -0 0</wrench>
        </link>
      </model>
      <model name='aws_robomaker_racetrack_Trackline_01_00'>
        <pose>-4.24539 0 0.102 0 -0 0</pose>
        <scale>1 1 1</scale>
        <link name='aws_Trackline_01::body'>
          <pose>-4.24539 0 0.102 0 -0 0</pose>
          <velocity>0 0 0 0 -0 0</velocity>
          <acceleration>0 0 0 0 -0 0</acceleration>
          <wrench>0 0 0 0 -0 0</wrench>
        </link>
      </model>
      <model name='ground_plane'>
        <pose>0 0 -735380 0 -0 0</pose>
        <scale>1 1 1</scale>
        <link name='link'>
          <pose>0 0 -735381 0 -0 0</pose>
          <velocity>0 0 -3796.5 0 -0 0</velocity>
          <acceleration>0 0 -9.8 0 -0 0</acceleration>
          <wrench>0 0 -9.8 0 -0 0</wrench>
        </link>
      </model>
      <model name='robot'>
        <pose>-5.35874 -15.0041 0.244359 -1e-06 0.008513 -0.003048</pose>
        <scale>1 1 1</scale>
        <link name='base_footprint'>
          <pose>-5.35874 -15.0041 0.244359 -1e-06 0.008513 -0.003048</pose>
          <velocity>0.000243 0.000349 5.2e-05 0.000368 0.000405 -0.001123</velocity>
          <acceleration>-0.060899 0.129622 0.353672 0.541233 -1.17575 -0.223986</acceleration>
          <wrench>-1.50604 3.20555 8.7463 0 -0 0</wrench>
        </link>
        <link name='fr_left_steer_link'>
          <pose>-4.80963 -14.7596 0.241908 7.2e-05 0.008929 -0.002672</pose>
          <velocity>-0.000438 0.000237 0.012605 0.015544 0.030387 0.000123</velocity>
          <acceleration>-2.3754 -1.03065 32.7071 -0.43144 -0.3079 2.06984</acceleration>
          <wrench>-0.023754 -0.010306 0.327071 0 -0 0</wrench>
        </link>
        <link name='fr_left_wheel_link'>
          <pose>-4.80963 -14.7596 0.241859 1.57079 -0.151975 0.014303</pose>
          <velocity>-0.000173 7.8e-05 0.010071 -0.00056 -0.001232 6.5e-05</velocity>
          <acceleration>-1.64541 -0.725818 26.1364 1.00367 1.07024 -3.04528</acceleration>
          <wrench>-4.93624 -2.17745 78.4093 0 -0 0</wrench>
        </link>
        <link name='fr_right_steer_link'>
          <pose>-4.80952 -15.252 0.2419 -0.000502 0.008899 -0.003347</pose>
          <velocity>-0.000114 -0.006074 0.0034 0.039631 0.02697 0.00249</velocity>
          <acceleration>-0.225347 -5.21099 5.49933 1.36118 -1.00502 -0.492116</acceleration>
          <wrench>-0.002253 -0.05211 0.054993 0 -0 0</wrench>
        </link>
        <link name='fr_right_wheel_link'>
          <pose>-4.80952 -15.252 0.241859 -1.5708 -0.016131 0.013632</pose>
          <velocity>-0.000112 -0.004375 0.001734 0.031256 -0.002334 0.003028</velocity>
          <acceleration>-0.088487 -3.62851 2.55673 -2.42331 1.27929 -0.358117</acceleration>
          <wrench>-0.265461 -10.8855 7.67018 0 -0 0</wrench>
        </link>
        <link name='re_left_wheel_link'>
          <pose>-5.35799 -14.7521 0.241859 1.57079 -0.338041 -0.003047</pose>
          <velocity>0.000517 0.000217 0.00012 -0.001504 0.002143 -0.003016</velocity>
          <acceleration>0.065445 0.0908 0.080255 -2.26185 -0.59263 -1.29301</acceleration>
          <wrench>0.196335 0.272399 0.240765 0 -0 0</wrench>
        </link>
        <link name='re_right_wheel_link'>
          <pose>-5.35953 -15.2561 0.241859 -1.5708 -0.809014 -0.003046</pose>
          <velocity>-1.7e-05 0.000329 -4e-06 -2.3e-05 -9.9e-05 -0.000254</velocity>
          <acceleration>-0.035188 0.226399 0.012049 0.713295 -0.009525 0.895413</acceleration>
          <wrench>-0.105563 0.679196 0.036148 0 -0 0</wrench>
        </link>
        <link name='virtual_steer_link'>
          <pose>-5.46961 -15.0038 0.400809 6.2e-05 0.008514 -0.003048</pose>
          <velocity>0.000308 0.000423 0.0001 -8e-06 0.000452 -0.001121</velocity>
          <acceleration>-0.148047 0.173152 -0.059295 0 -0 0</acceleration>
          <wrench>-0.000148 0.000173 -5.9e-05 0 -0 0</wrench>
        </link>
      </model>
      <light name='sun'>
        <pose>0 0 10 0.65 0.15 0</pose>
      </light>
      <light name='sun2'>
        <pose>0 0 10 0.65 0.15 0</pose>
      </light>
      <light name='user_point_light_0'>
        <pose>4 -14.6516 3.9 0 -0 0</pose>
      </light>
      <light name='user_point_light_1'>
        <pose>3.88413 -14.1477 3.9 0 -0 0</pose>
      </light>
      <light name='user_point_light_2'>
        <pose>4 -15.1089 3.91259 0 -0 0</pose>
      </light>
      <light name='user_point_light_3'>
        <pose>4 -15.577 3.9 0 -0 0</pose>
      </light>
    </state>
    <light name='sun' type='directional'>
      <cast_shadows>1</cast_shadows>
      <pose>0 0 10 0 -0 0</pose>
      <diffuse>1 1 1 1</diffuse>
      <specular>1 1 1 1</specular>
      <attenuation>
        <range>1000</range>
        <constant>0.9</constant>
        <linear>0.01</linear>
        <quadratic>0.001</quadratic>
      </attenuation>
      <direction>-0.5 0.1 -0.9</direction>
      <spot>
        <inner_angle>0</inner_angle>
        <outer_angle>0</outer_angle>
        <falloff>0</falloff>
      </spot>
    </light>
    <light name='sun2' type='directional'>
      <cast_shadows>1</cast_shadows>
      <pose>0 0 10 0 -0 0</pose>
      <diffuse>1 1 1 1</diffuse>
      <specular>1 1 1 1</specular>
      <attenuation>
        <range>1000</range>
        <constant>0.9</constant>
        <linear>0.01</linear>
        <quadratic>0.001</quadratic>
      </attenuation>
      <direction>-0.5 0.1 -0.9</direction>
      <spot>
        <inner_angle>0</inner_angle>
        <outer_angle>0</outer_angle>
        <falloff>0</falloff>
      </spot>
    </light>
    <light name='user_point_light_0' type='point'>
      <pose>1.49278 -15.5363 1 0 -0 0</pose>
      <diffuse>0 0.98039 0 1</diffuse>
      <specular>0.1 0.1 0.1 1</specular>
      <attenuation>
        <range>0.3</range>
        <constant>0.02</constant>
        <linear>0.01</linear>
        <quadratic>0</quadratic>
      </attenuation>
      <cast_shadows>0</cast_shadows>
      <direction>0 0 -1</direction>
      <spot>
        <inner_angle>0</inner_angle>
        <outer_angle>0</outer_angle>
        <falloff>0</falloff>
      </spot>
    </light>
    <light name='user_point_light_1' type='point'>
      <pose>6.99411 -11.55 1 0 -0 0</pose>
      <diffuse>0 0.98039 0 1</diffuse>
      <specular>0.1 0.1 0.1 1</specular>
      <attenuation>
        <range>0.3</range>
        <constant>0.02</constant>
        <linear>0.01</linear>
        <quadratic>0</quadratic>
      </attenuation>
      <cast_shadows>0</cast_shadows>
      <direction>0 0 -1</direction>
      <spot>
        <inner_angle>0</inner_angle>
        <outer_angle>0</outer_angle>
        <falloff>0</falloff>
      </spot>
    </light>
    <light name='user_point_light_2' type='point'>
      <pose>5.65528 -14.8924 1 0 -0 0</pose>
      <diffuse>0 0.98039 0 1</diffuse>
      <specular>0.1 0.1 0.1 1</specular>
      <attenuation>
        <range>0.3</range>
        <constant>0.02</constant>
        <linear>0.01</linear>
        <quadratic>0</quadratic>
      </attenuation>
      <cast_shadows>0</cast_shadows>
      <direction>0 0 -1</direction>
      <spot>
        <inner_angle>0</inner_angle>
        <outer_angle>0</outer_angle>
        <falloff>0</falloff>
      </spot>
    </light>
    <light name='user_point_light_3' type='point'>
      <pose>3.6452 -17.3437 1 0 -0 0</pose>
      <diffuse>0 0.98039 0 1</diffuse>
      <specular>0.1 0.1 0.1 1</specular>
      <attenuation>
        <range>0.3</range>
        <constant>0.02</constant>
        <linear>0.01</linear>
        <quadratic>0</quadratic>
      </attenuation>
      <cast_shadows>0</cast_shadows>
      <direction>0 0 -1</direction>
      <spot>
        <inner_angle>0</inner_angle>
        <outer_angle>0</outer_angle>
        <falloff>0</falloff>
      </spot>
    </light>
    <audio>
      <device>default</device>
    </audio>
    <wind/>
    <model name='robot'>
      <link name='base_footprint'>
        <inertial>
          <pose>0.245214 -0.000373 0.078372 0 -0 0</pose>
          <mass>24.73</mass>
          <inertia>
            <ixx>0.208333</ixx>
            <ixy>0</ixy>
            <ixz>5.55112e-17</ixz>
            <iyy>1.19271</iyy>
            <iyz>0</iyz>
            <izz>1.35938</izz>
          </inertia>
        </inertial>
        <collision name='base_footprint_fixed_joint_lump__chassis_link_collision'>
          <pose>0.2778 0 0.1055 0 -0 0</pose>
          <geometry>
            <box>
              <size>0.75 0.3 0.1</size>
            </box>
          </geometry>
          <surface>
            <contact>
              <ode/>
            </contact>
            <friction>
              <ode>
                <mu>0.5</mu>
                <mu2>0.5</mu2>
              </ode>
              <torsional>
                <ode/>
              </torsional>
            </friction>
            <bounce/>
          </surface>
          <max_contacts>10</max_contacts>
        </collision>
        <visual name='base_footprint_fixed_joint_lump__chassis_link_visual'>
          <pose>0.2078 0 0.1555 0 -0 0</pose>
          <geometry>
            <box>
              <size>0.75 0.3 0.1</size>
            </box>
          </geometry>
          <material>
            <script>
              <name>Gazebo/White</name>
              <uri>file://media/materials/scripts/gazebo.material</uri>
            </script>
          </material>
        </visual>
        <sensor name='zed_camera' type='camera'>
          <update_rate>30</update_rate>
          <camera name='camera'>
            <horizontal_fov>0.870922</horizontal_fov>
            <image>
              <width>640</width>
              <height>480</height>
              <format>B8G8R8</format>
            </image>
            <clip>
              <near>0.02</near>
              <far>300</far>
            </clip>
            <noise>
              <type>gaussian</type>
              <mean>0</mean>
              <stddev>0.007</stddev>
            </noise>
          </camera>
          <plugin name='camera_controller' filename='libgazebo_ros_camera.so'>
            <alwaysOn>1</alwaysOn>
            <updateRate>30.0</updateRate>
            <cameraName>/camera</cameraName>
            <imageTopicName>rgb/image_rect_color</imageTopicName>
            <cameraInfoTopicName>rgb/camera_info</cameraInfoTopicName>
            <frameName>camera_link</frameName>
            <hackBaseline>0</hackBaseline>
            <distortionK1>0.0</distortionK1>
            <distortionK2>0.0</distortionK2>
            <distortionK3>0.0</distortionK3>
            <distortionT1>0.0</distortionT1>
            <distortionT2>0.0</distortionT2>
          </plugin>
          <pose>0 0 1 0 -0 0</pose>
        </sensor>
        <sensor name='laser_sensor' type='ray'>
          <visualize>0</visualize>
          <update_rate>10</update_rate>
          <ray>
            <scan>
              <horizontal>
                <samples>360</samples>
                <resolution>1</resolution>
                <min_angle>-3.14159</min_angle>
                <max_angle>3.14159</max_angle>
              </horizontal>
              <vertical>
                <samples>1</samples>
                <min_angle>0</min_angle>
                <max_angle>0</max_angle>
              </vertical>
            </scan>
            <range>
              <min>0.1</min>
              <max>10</max>
              <resolution>0.01</resolution>
            </range>
            <noise>
              <type>gaussian</type>
              <mean>0</mean>
              <stddev>0.01</stddev>
            </noise>
          </ray>
          <plugin name='gazebo_ros_laser_controller' filename='libgazebo_ros_ray_sensor.so'>
            <ros>
              <namespace>/</namespace>
              <remapping>~/out:=scan</remapping>
            </ros>
            <output_type>sensor_msgs/LaserScan</output_type>
            <frame_name>lidar_link</frame_name>
          </plugin>
          <pose>0 0 0.6 0 -0 0</pose>
        </sensor>
        <self_collide>0</self_collide>
        <enable_wind>0</enable_wind>
        <kinematic>0</kinematic>
      </link>
      <joint name='fr_left_steer_joint' type='revolute'>
        <pose relative_to='base_footprint'>0.54838 0.24619 0.002 0 -0 0</pose>
        <parent>base_footprint</parent>
        <child>fr_left_steer_link</child>
        <axis>
          <xyz>0 0 1</xyz>
          <limit>
            <lower>-0.6</lower>
            <upper>0.6</upper>
            <effort>-1</effort>
            <velocity>-1</velocity>
          </limit>
          <dynamics>
            <spring_reference>0</spring_reference>
            <spring_stiffness>0</spring_stiffness>
          </dynamics>
        </axis>
      </joint>
      <link name='fr_left_steer_link'>
        <pose relative_to='fr_left_steer_joint'>0 0 0 0 -0 0</pose>
        <inertial>
          <pose>-0.000278 0.016354 0 0 -0 0</pose>
          <mass>0.01</mass>
          <inertia>
            <ixx>6.53333e-05</ixx>
            <ixy>0</ixy>
            <ixz>0</ixz>
            <iyy>6.53333e-05</iyy>
            <iyz>0</iyz>
            <izz>9.8e-05</izz>
          </inertia>
        </inertial>
        <self_collide>0</self_collide>
        <enable_wind>0</enable_wind>
        <kinematic>0</kinematic>
      </link>
      <joint name='fr_left_wheel_joint' type='revolute'>
        <pose relative_to='fr_left_steer_link'>0 0 0 1.5708 -0 0.016976</pose>
        <parent>fr_left_steer_link</parent>
        <child>fr_left_wheel_link</child>
        <axis>
          <xyz>0 0 -1</xyz>
          <limit>
            <effort>200</effort>
            <velocity>-1</velocity>
            <lower>-1e+16</lower>
            <upper>1e+16</upper>
          </limit>
          <dynamics>
            <damping>0.5</damping>
            <friction>0.8</friction>
            <spring_reference>0</spring_reference>
            <spring_stiffness>0</spring_stiffness>
          </dynamics>
        </axis>
      </joint>
      <link name='fr_left_wheel_link'>
        <pose relative_to='fr_left_wheel_joint'>0 0 0 0 -0 0</pose>
        <inertial>
          <pose>-0 0 -0.016356 0 -0 0</pose>
          <mass>3</mass>
          <inertia>
            <ixx>0.0196</ixx>
            <ixy>0</ixy>
            <ixz>0</ixz>
            <iyy>0.0196</iyy>
            <iyz>0</iyz>
            <izz>0.0294</izz>
          </inertia>
        </inertial>
        <collision name='fr_left_wheel_link_collision'>
          <pose>0 0 0 0 -0 0</pose>
          <geometry>
            <cylinder>
              <length>0.14</length>
              <radius>0.14</radius>
            </cylinder>
          </geometry>
          <surface>
            <contact>
              <ode/>
            </contact>
            <friction>
              <ode>
                <mu>1</mu>
                <mu2>1</mu2>
              </ode>
              <torsional>
                <ode/>
              </torsional>
            </friction>
            <bounce/>
          </surface>
          <max_contacts>10</max_contacts>
        </collision>
        <visual name='fr_left_wheel_link_visual'>
          <pose>0 0 0 0 -0 0</pose>
          <geometry>
            <cylinder>
              <length>0.14</length>
              <radius>0.14</radius>
            </cylinder>
          </geometry>
          <material>
            <script>
              <name>Gazebo/Grey</name>
              <uri>file://media/materials/scripts/gazebo.material</uri>
            </script>
          </material>
        </visual>
        <self_collide>0</self_collide>
        <enable_wind>0</enable_wind>
        <kinematic>0</kinematic>
      </link>
      <joint name='fr_right_steer_joint' type='revolute'>
        <pose relative_to='base_footprint'>0.54999 -0.24619 0.002 0 -0 0</pose>
        <parent>base_footprint</parent>
        <child>fr_right_steer_link</child>
        <axis>
          <xyz>0 0 1</xyz>
          <limit>
            <lower>-0.6</lower>
            <upper>0.6</upper>
            <effort>-1</effort>
            <velocity>-1</velocity>
          </limit>
          <dynamics>
            <spring_reference>0</spring_reference>
            <spring_stiffness>0</spring_stiffness>
          </dynamics>
        </axis>
      </joint>
      <link name='fr_right_steer_link'>
        <pose relative_to='fr_right_steer_joint'>0 0 0 0 -0 0</pose>
        <inertial>
          <pose>0.000275 -0.016354 -0 0 -0 0</pose>
          <mass>0.01</mass>
          <inertia>
            <ixx>6.53333e-05</ixx>
            <ixy>0</ixy>
            <ixz>0</ixz>
            <iyy>6.53333e-05</iyy>
            <iyz>0</iyz>
            <izz>9.8e-05</izz>
          </inertia>
        </inertial>
        <self_collide>0</self_collide>
        <enable_wind>0</enable_wind>
        <kinematic>0</kinematic>
      </link>
      <joint name='fr_right_wheel_joint' type='revolute'>
        <pose relative_to='fr_right_steer_link'>0 0 0 -1.5708 0 0.016976</pose>
        <parent>fr_right_steer_link</parent>
        <child>fr_right_wheel_link</child>
        <axis>
          <xyz>0 0 1</xyz>
          <limit>
            <effort>200</effort>
            <velocity>-1</velocity>
            <lower>-1e+16</lower>
            <upper>1e+16</upper>
          </limit>
          <dynamics>
            <damping>0.5</damping>
            <friction>0.8</friction>
            <spring_reference>0</spring_reference>
            <spring_stiffness>0</spring_stiffness>
          </dynamics>
        </axis>
      </joint>
      <link name='fr_right_wheel_link'>
        <pose relative_to='fr_right_wheel_joint'>0 0 0 0 -0 0</pose>
        <inertial>
          <pose>0.000275 0 -0.016354 0 -0 0</pose>
          <mass>3</mass>
          <inertia>
            <ixx>0.0196</ixx>
            <ixy>0</ixy>
            <ixz>0</ixz>
            <iyy>0.0196</iyy>
            <iyz>0</iyz>
            <izz>0.0294</izz>
          </inertia>
        </inertial>
        <collision name='fr_right_wheel_link_collision'>
          <pose>0 0 0 0 -0 0</pose>
          <geometry>
            <cylinder>
              <length>0.14</length>
              <radius>0.14</radius>
            </cylinder>
          </geometry>
          <surface>
            <contact>
              <ode/>
            </contact>
            <friction>
              <ode>
                <mu>1</mu>
                <mu2>1</mu2>
              </ode>
              <torsional>
                <ode/>
              </torsional>
            </friction>
            <bounce/>
          </surface>
          <max_contacts>10</max_contacts>
        </collision>
        <visual name='fr_right_wheel_link_visual'>
          <pose>0 0 0 0 -0 0</pose>
          <geometry>
            <cylinder>
              <length>0.14</length>
              <radius>0.14</radius>
            </cylinder>
          </geometry>
          <material>
            <script>
              <name>Gazebo/Grey</name>
              <uri>file://media/materials/scripts/gazebo.material</uri>
            </script>
          </material>
        </visual>
        <self_collide>0</self_collide>
        <enable_wind>0</enable_wind>
        <kinematic>0</kinematic>
      </link>
      <joint name='re_left_wheel_joint' type='revolute'>
        <pose relative_to='base_footprint'>0 0.252 -0.0025 1.5708 -0 0</pose>
        <parent>base_footprint</parent>
        <child>re_left_wheel_link</child>
        <axis>
          <xyz>0 0 -1</xyz>
          <limit>
            <effort>70</effort>
            <velocity>-1</velocity>
            <lower>-1e+16</lower>
            <upper>1e+16</upper>
          </limit>
          <dynamics>
            <damping>0.5</damping>
            <friction>0.8</friction>
            <spring_reference>0</spring_reference>
            <spring_stiffness>0</spring_stiffness>
          </dynamics>
        </axis>
      </joint>
      <link name='re_left_wheel_link'>
        <pose relative_to='re_left_wheel_joint'>0 0 0 0 -0 0</pose>
        <inertial>
          <pose>0 2e-06 -0.010284 0 -0 0</pose>
          <mass>3</mass>
          <inertia>
            <ixx>0.0196</ixx>
            <ixy>0</ixy>
            <ixz>0</ixz>
            <iyy>0.0196</iyy>
            <iyz>0</iyz>
            <izz>0.0294</izz>
          </inertia>
        </inertial>
        <collision name='re_left_wheel_link_collision'>
          <pose>0 0 0 0 -0 0</pose>
          <geometry>
            <cylinder>
              <length>0.14</length>
              <radius>0.14</radius>
            </cylinder>
          </geometry>
          <surface>
            <contact>
              <ode/>
            </contact>
            <friction>
              <ode>
                <mu>1</mu>
                <mu2>1</mu2>
              </ode>
              <torsional>
                <ode/>
              </torsional>
            </friction>
            <bounce/>
          </surface>
          <max_contacts>10</max_contacts>
        </collision>
        <visual name='re_left_wheel_link_visual'>
          <pose>0 0 0 0 -0 0</pose>
          <geometry>
            <cylinder>
              <length>0.14</length>
              <radius>0.14</radius>
            </cylinder>
          </geometry>
          <material>
            <script>
              <name>Gazebo/Grey</name>
              <uri>file://media/materials/scripts/gazebo.material</uri>
            </script>
          </material>
        </visual>
        <self_collide>0</self_collide>
        <enable_wind>0</enable_wind>
        <kinematic>0</kinematic>
      </link>
      <joint name='re_right_wheel_joint' type='revolute'>
        <pose relative_to='base_footprint'>0 -0.252 -0.0025 -1.5708 0 0</pose>
        <parent>base_footprint</parent>
        <child>re_right_wheel_link</child>
        <axis>
          <xyz>0 0 1</xyz>
          <limit>
            <effort>70</effort>
            <velocity>-1</velocity>
            <lower>-1e+16</lower>
            <upper>1e+16</upper>
          </limit>
          <dynamics>
            <damping>0.5</damping>
            <friction>0.8</friction>
            <spring_reference>0</spring_reference>
            <spring_stiffness>0</spring_stiffness>
          </dynamics>
        </axis>
      </joint>
      <link name='re_right_wheel_link'>
        <pose relative_to='re_right_wheel_joint'>0 0 0 0 -0 0</pose>
        <inertial>
          <pose>0 0 0 0 -0 0</pose>
          <mass>3</mass>
          <inertia>
            <ixx>0.0196</ixx>
            <ixy>0</ixy>
            <ixz>0</ixz>
            <iyy>0.0196</iyy>
            <iyz>0</iyz>
            <izz>0.0294</izz>
          </inertia>
        </inertial>
        <collision name='re_right_wheel_link_collision'>
          <pose>0 0 0 0 -0 0</pose>
          <geometry>
            <cylinder>
              <length>0.14</length>
              <radius>0.14</radius>
            </cylinder>
          </geometry>
          <surface>
            <contact>
              <ode/>
            </contact>
            <friction>
              <ode>
                <mu>1</mu>
                <mu2>1</mu2>
              </ode>
              <torsional>
                <ode/>
              </torsional>
            </friction>
            <bounce/>
          </surface>
          <max_contacts>10</max_contacts>
        </collision>
        <visual name='re_right_wheel_link_visual'>
          <pose>0 0 0 0 -0 0</pose>
          <geometry>
            <cylinder>
              <length>0.14</length>
              <radius>0.14</radius>
            </cylinder>
          </geometry>
          <material>
            <script>
              <name>Gazebo/Grey</name>
              <uri>file://media/materials/scripts/gazebo.material</uri>
            </script>
          </material>
        </visual>
        <self_collide>0</self_collide>
        <enable_wind>0</enable_wind>
        <kinematic>0</kinematic>
      </link>
      <joint name='virtual_steering_wheel_joint' type='revolute'>
        <pose relative_to='base_footprint'>-0.1122 0 0.1555 0 -0 0</pose>
        <parent>base_footprint</parent>
        <child>virtual_steer_link</child>
        <axis>
          <xyz>-1 0 0</xyz>
          <limit>
            <lower>-3</lower>
            <upper>3</upper>
            <effort>200</effort>
            <velocity>20</velocity>
          </limit>
          <dynamics>
            <spring_reference>0</spring_reference>
            <spring_stiffness>0</spring_stiffness>
          </dynamics>
        </axis>
      </joint>
      <link name='virtual_steer_link'>
        <pose relative_to='virtual_steering_wheel_joint'>0 0 0 0 -0 0</pose>
        <inertial>
          <pose>0 0 0 0 -0 0</pose>
          <mass>0.001</mass>
          <inertia>
            <ixx>0</ixx>
            <ixy>0</ixy>
            <ixz>0</ixz>
            <iyy>0</iyy>
            <iyz>0</iyz>
            <izz>0</izz>
          </inertia>
        </inertial>
        <visual name='virtual_steer_link_visual'>
          <pose>0 0 0 0 -0 0</pose>
          <geometry>
            <box>
              <size>0.01 0.15 0.075</size>
            </box>
          </geometry>
          <material>
            <script>
              <name>Gazebo/Yellow</name>
              <uri>file://media/materials/scripts/gazebo.material</uri>
            </script>
          </material>
        </visual>
        <self_collide>0</self_collide>
        <enable_wind>0</enable_wind>
        <kinematic>0</kinematic>
      </link>
      <plugin name='gazebo_ros_joint_state_publisher' filename='libgazebo_ros_joint_state_publisher.so'>
        <update_rate>100</update_rate>
        <joint_name>fr_right_steer_joint</joint_name>
        <joint_name>fr_right_wheel_joint</joint_name>
        <joint_name>fr_left_steer_joint</joint_name>
        <joint_name>fr_left_wheel_joint</joint_name>
        <joint_name>re_right_wheel_joint</joint_name>
        <joint_name>re_left_wheel_joint</joint_name>
        <joint_name>virtual_steering_wheel_joint</joint_name>
      </plugin>
      <plugin name='gazebo_ros_joint_pose_trajectory' filename='libgazebo_ros_joint_pose_trajectory.so'>
        <update_rate>2</update_rate>
      </plugin>
      <static>0</static>
      <plugin name='gazebo_ackermann_drive' filename='libgazebo_ros_ackermann_drive.so'>
        <ros>
          <remapping>cmd_vel:=cmd_vel</remapping>
          <remapping>odom:=odom/bot</remapping>
          <remapping>distance:=distance/bot</remapping>
        </ros>
        <update_rate>100.0</update_rate>
        <front_left_joint>fr_left_wheel_joint</front_left_joint>
        <front_right_joint>fr_right_wheel_joint</front_right_joint>
        <rear_left_joint>re_left_wheel_joint</rear_left_joint>
        <rear_right_joint>re_right_wheel_joint</rear_right_joint>
        <left_steering_joint>fr_left_steer_joint</left_steering_joint>
        <right_steering_joint>fr_right_steer_joint</right_steering_joint>
        <steering_wheel_joint>virtual_steering_wheel_joint</steering_wheel_joint>
        <max_steer>0.383972</max_steer>
        <max_steering_angle>1.570796</max_steering_angle>
        <max_speed>5</max_speed>
        <left_steering_pid_gain>1500 0 1</left_steering_pid_gain>
        <left_steering_i_range>0 0</left_steering_i_range>
        <right_steering_pid_gain>1500 0 1</right_steering_pid_gain>
        <right_steering_i_range>0 0</right_steering_i_range>
        <linear_velocity_pid_gain>1500 0 1</linear_velocity_pid_gain>
        <linear_velocity_i_range>0 0</linear_velocity_i_range>
        <publish_odom>1</publish_odom>
        <publish_odom_tf>1</publish_odom_tf>
        <publish_wheel_tf>0</publish_wheel_tf>
        <publish_distance>1</publish_distance>
        <odometry_frame>odom</odometry_frame>
        <robot_base_frame>base_footprint</robot_base_frame>
      </plugin>
      <pose>-5.5 -15 0.1 0 -0 0</pose>
    </model>
  </world>
</sdf>
